 * Serving Flask app 'frontend_service'
 * Debug mode: off
WARNING: This is a development server. Do not use it in a production deployment. Use a production WSGI server instead.
 * Running on all addresses (0.0.0.0)
 * Running on http://127.0.0.1:5003
 * Running on http://168.119.248.211:5003
Press CTRL+C to quit
78.154.13.190 - - [10/Jan/2024 14:29:51] "GET / HTTP/1.1" 200 -
[2024-01-10 14:30:01,610] ERROR in app: Exception on /register [POST]
Traceback (most recent call last):
  File "/usr/lib/python3/dist-packages/urllib3/connection.py", line 169, in _new_conn
    conn = connection.create_connection(
  File "/usr/lib/python3/dist-packages/urllib3/util/connection.py", line 96, in create_connection
    raise err
  File "/usr/lib/python3/dist-packages/urllib3/util/connection.py", line 86, in create_connection
    sock.connect(sa)
ConnectionRefusedError: [Errno 111] Connection refused

During handling of the above exception, another exception occurred:

Traceback (most recent call last):
  File "/usr/lib/python3/dist-packages/urllib3/connectionpool.py", line 700, in urlopen
    httplib_response = self._make_request(
  File "/usr/lib/python3/dist-packages/urllib3/connectionpool.py", line 395, in _make_request
    conn.request(method, url, **httplib_request_kw)
  File "/usr/lib/python3/dist-packages/urllib3/connection.py", line 234, in request
    super(HTTPConnection, self).request(method, url, body=body, headers=headers)
  File "/usr/lib/python3.10/http/client.py", line 1283, in request
    self._send_request(method, url, body, headers, encode_chunked)
  File "/usr/lib/python3.10/http/client.py", line 1329, in _send_request
    self.endheaders(body, encode_chunked=encode_chunked)
  File "/usr/lib/python3.10/http/client.py", line 1278, in endheaders
    self._send_output(message_body, encode_chunked=encode_chunked)
  File "/usr/lib/python3.10/http/client.py", line 1038, in _send_output
    self.send(msg)
  File "/usr/lib/python3.10/http/client.py", line 976, in send
    self.connect()
  File "/usr/lib/python3/dist-packages/urllib3/connection.py", line 200, in connect
    conn = self._new_conn()
  File "/usr/lib/python3/dist-packages/urllib3/connection.py", line 181, in _new_conn
    raise NewConnectionError(
urllib3.exceptions.NewConnectionError: <urllib3.connection.HTTPConnection object at 0x7f972ec9f010>: Failed to establish a new connection: [Errno 111] Connection refused

During handling of the above exception, another exception occurred:

Traceback (most recent call last):
  File "/usr/local/lib/python3.10/dist-packages/requests/adapters.py", line 486, in send
    resp = conn.urlopen(
  File "/usr/lib/python3/dist-packages/urllib3/connectionpool.py", line 756, in urlopen
    retries = retries.increment(
  File "/usr/lib/python3/dist-packages/urllib3/util/retry.py", line 574, in increment
    raise MaxRetryError(_pool, url, error or ResponseError(cause))
urllib3.exceptions.MaxRetryError: HTTPConnectionPool(host='localhost', port=5001): Max retries exceeded with url: /register (Caused by NewConnectionError('<urllib3.connection.HTTPConnection object at 0x7f972ec9f010>: Failed to establish a new connection: [Errno 111] Connection refused'))

During handling of the above exception, another exception occurred:

Traceback (most recent call last):
  File "/home/georgi/.local/lib/python3.10/site-packages/flask/app.py", line 1455, in wsgi_app
    response = self.full_dispatch_request()
  File "/home/georgi/.local/lib/python3.10/site-packages/flask/app.py", line 869, in full_dispatch_request
    rv = self.handle_user_exception(e)
  File "/home/georgi/.local/lib/python3.10/site-packages/flask/app.py", line 867, in full_dispatch_request
    rv = self.dispatch_request()
  File "/home/georgi/.local/lib/python3.10/site-packages/flask/app.py", line 852, in dispatch_request
    return self.ensure_sync(self.view_functions[rule.endpoint])(**view_args)
  File "/home/georgi/DevOps/python_app/frontend-service/frontend_service.py", line 17, in handle_registration
    response = requests.post('http://localhost:5001/register', json={'username': username, 'password': password})
  File "/usr/local/lib/python3.10/dist-packages/requests/api.py", line 115, in post
    return request("post", url, data=data, json=json, **kwargs)
  File "/usr/local/lib/python3.10/dist-packages/requests/api.py", line 59, in request
    return session.request(method=method, url=url, **kwargs)
  File "/usr/local/lib/python3.10/dist-packages/requests/sessions.py", line 589, in request
    resp = self.send(prep, **send_kwargs)
  File "/usr/local/lib/python3.10/dist-packages/requests/sessions.py", line 703, in send
    r = adapter.send(request, **kwargs)
  File "/usr/local/lib/python3.10/dist-packages/requests/adapters.py", line 519, in send
    raise ConnectionError(e, request=request)
requests.exceptions.ConnectionError: HTTPConnectionPool(host='localhost', port=5001): Max retries exceeded with url: /register (Caused by NewConnectionError('<urllib3.connection.HTTPConnection object at 0x7f972ec9f010>: Failed to establish a new connection: [Errno 111] Connection refused'))
78.154.13.190 - - [10/Jan/2024 14:30:01] "POST /register HTTP/1.1" 500 -
[2024-01-10 14:31:50,853] ERROR in app: Exception on /store [POST]
Traceback (most recent call last):
  File "/usr/lib/python3/dist-packages/urllib3/connection.py", line 169, in _new_conn
    conn = connection.create_connection(
  File "/usr/lib/python3/dist-packages/urllib3/util/connection.py", line 96, in create_connection
    raise err
  File "/usr/lib/python3/dist-packages/urllib3/util/connection.py", line 86, in create_connection
    sock.connect(sa)
ConnectionRefusedError: [Errno 111] Connection refused

During handling of the above exception, another exception occurred:

Traceback (most recent call last):
  File "/usr/lib/python3/dist-packages/urllib3/connectionpool.py", line 700, in urlopen
    httplib_response = self._make_request(
  File "/usr/lib/python3/dist-packages/urllib3/connectionpool.py", line 395, in _make_request
    conn.request(method, url, **httplib_request_kw)
  File "/usr/lib/python3/dist-packages/urllib3/connection.py", line 234, in request
    super(HTTPConnection, self).request(method, url, body=body, headers=headers)
  File "/usr/lib/python3.10/http/client.py", line 1283, in request
    self._send_request(method, url, body, headers, encode_chunked)
  File "/usr/lib/python3.10/http/client.py", line 1329, in _send_request
    self.endheaders(body, encode_chunked=encode_chunked)
  File "/usr/lib/python3.10/http/client.py", line 1278, in endheaders
    self._send_output(message_body, encode_chunked=encode_chunked)
  File "/usr/lib/python3.10/http/client.py", line 1038, in _send_output
    self.send(msg)
  File "/usr/lib/python3.10/http/client.py", line 976, in send
    self.connect()
  File "/usr/lib/python3/dist-packages/urllib3/connection.py", line 200, in connect
    conn = self._new_conn()
  File "/usr/lib/python3/dist-packages/urllib3/connection.py", line 181, in _new_conn
    raise NewConnectionError(
urllib3.exceptions.NewConnectionError: <urllib3.connection.HTTPConnection object at 0x7f972ec9fb20>: Failed to establish a new connection: [Errno 111] Connection refused

During handling of the above exception, another exception occurred:

Traceback (most recent call last):
  File "/usr/local/lib/python3.10/dist-packages/requests/adapters.py", line 486, in send
    resp = conn.urlopen(
  File "/usr/lib/python3/dist-packages/urllib3/connectionpool.py", line 756, in urlopen
    retries = retries.increment(
  File "/usr/lib/python3/dist-packages/urllib3/util/retry.py", line 574, in increment
    raise MaxRetryError(_pool, url, error or ResponseError(cause))
urllib3.exceptions.MaxRetryError: HTTPConnectionPool(host='localhost', port=5002): Max retries exceeded with url: /store (Caused by NewConnectionError('<urllib3.connection.HTTPConnection object at 0x7f972ec9fb20>: Failed to establish a new connection: [Errno 111] Connection refused'))

During handling of the above exception, another exception occurred:

Traceback (most recent call last):
  File "/home/georgi/.local/lib/python3.10/site-packages/flask/app.py", line 1455, in wsgi_app
    response = self.full_dispatch_request()
  File "/home/georgi/.local/lib/python3.10/site-packages/flask/app.py", line 869, in full_dispatch_request
    rv = self.handle_user_exception(e)
  File "/home/georgi/.local/lib/python3.10/site-packages/flask/app.py", line 867, in full_dispatch_request
    rv = self.dispatch_request()
  File "/home/georgi/.local/lib/python3.10/site-packages/flask/app.py", line 852, in dispatch_request
    return self.ensure_sync(self.view_functions[rule.endpoint])(**view_args)
  File "/home/georgi/DevOps/python_app/frontend-service/frontend_service.py", line 35, in store_data
    response = requests.post('http://localhost:5002/store', json={'user': user, 'message': message})
  File "/usr/local/lib/python3.10/dist-packages/requests/api.py", line 115, in post
    return request("post", url, data=data, json=json, **kwargs)
  File "/usr/local/lib/python3.10/dist-packages/requests/api.py", line 59, in request
    return session.request(method=method, url=url, **kwargs)
  File "/usr/local/lib/python3.10/dist-packages/requests/sessions.py", line 589, in request
    resp = self.send(prep, **send_kwargs)
  File "/usr/local/lib/python3.10/dist-packages/requests/sessions.py", line 703, in send
    r = adapter.send(request, **kwargs)
  File "/usr/local/lib/python3.10/dist-packages/requests/adapters.py", line 519, in send
    raise ConnectionError(e, request=request)
requests.exceptions.ConnectionError: HTTPConnectionPool(host='localhost', port=5002): Max retries exceeded with url: /store (Caused by NewConnectionError('<urllib3.connection.HTTPConnection object at 0x7f972ec9fb20>: Failed to establish a new connection: [Errno 111] Connection refused'))
78.154.13.190 - - [10/Jan/2024 14:31:50] "POST /store HTTP/1.1" 500 -
78.154.13.190 - - [10/Jan/2024 14:36:26] "GET / HTTP/1.1" 200 -
 * Serving Flask app 'frontend_service'
 * Debug mode: off
WARNING: This is a development server. Do not use it in a production deployment. Use a production WSGI server instead.
 * Running on all addresses (0.0.0.0)
 * Running on http://127.0.0.1:5003
 * Running on http://168.119.248.211:5003
Press CTRL+C to quit
78.154.13.190 - - [10/Jan/2024 14:42:37] "GET / HTTP/1.1" 200 -
78.154.13.190 - - [10/Jan/2024 14:42:39] "GET / HTTP/1.1" 200 -
78.154.13.190 - - [10/Jan/2024 14:42:41] "GET / HTTP/1.1" 200 -
78.154.13.190 - - [10/Jan/2024 14:42:46] "POST /register HTTP/1.1" 200 -
78.154.13.190 - - [10/Jan/2024 14:43:05] "GET / HTTP/1.1" 200 -
78.154.13.190 - - [10/Jan/2024 14:43:10] "POST /login HTTP/1.1" 200 -
78.154.13.190 - - [10/Jan/2024 14:43:17] "GET / HTTP/1.1" 200 -
78.154.13.190 - - [10/Jan/2024 14:43:25] "POST /store HTTP/1.1" 200 -
78.154.13.190 - - [10/Jan/2024 14:44:56] "GET / HTTP/1.1" 200 -
78.154.13.190 - - [10/Jan/2024 14:45:42] "GET / HTTP/1.1" 200 -
78.154.13.190 - - [10/Jan/2024 14:45:46] "GET / HTTP/1.1" 200 -
 * Serving Flask app 'frontend_service'
 * Debug mode: off
WARNING: This is a development server. Do not use it in a production deployment. Use a production WSGI server instead.
 * Running on all addresses (0.0.0.0)
 * Running on http://127.0.0.1:5003
 * Running on http://168.119.248.211:5003
Press CTRL+C to quit
78.154.13.190 - - [10/Jan/2024 14:47:57] "GET / HTTP/1.1" 200 -
78.154.13.190 - - [10/Jan/2024 14:48:23] "POST /register HTTP/1.1" 200 -
78.154.13.190 - - [10/Jan/2024 14:48:34] "POST /login HTTP/1.1" 200 -
78.154.13.190 - - [10/Jan/2024 14:48:39] "POST /login HTTP/1.1" 200 -
78.154.13.190 - - [10/Jan/2024 14:53:31] "POST /register HTTP/1.1" 200 -
78.154.13.190 - - [10/Jan/2024 15:26:09] "GET / HTTP/1.1" 200 -
78.154.13.190 - - [10/Jan/2024 15:27:34] "GET /favicon.ico HTTP/1.1" 404 -
78.154.13.190 - - [10/Jan/2024 15:27:38] "GET / HTTP/1.1" 200 -
78.154.13.190 - - [10/Jan/2024 15:29:28] "GET / HTTP/1.1" 200 -
78.154.13.190 - - [10/Jan/2024 16:20:51] "GET / HTTP/1.1" 200 -
78.154.13.190 - - [10/Jan/2024 16:21:22] "POST /store HTTP/1.1" 200 -
78.154.13.190 - - [10/Jan/2024 16:23:18] "GET / HTTP/1.1" 200 -
78.154.13.190 - - [10/Jan/2024 16:25:33] "GET / HTTP/1.1" 200 -
78.154.13.190 - - [10/Jan/2024 16:49:29] "GET /favicon.ico HTTP/1.1" 404 -
78.154.13.190 - - [10/Jan/2024 16:58:11] "GET /favicon.ico HTTP/1.1" 404 -
78.154.13.190 - - [10/Jan/2024 17:09:20] "GET / HTTP/1.1" 200 -
78.154.13.190 - - [10/Jan/2024 17:09:25] "GET / HTTP/1.1" 200 -
78.154.13.190 - - [10/Jan/2024 19:28:15] "GET / HTTP/1.1" 200 -
165.154.225.234 - - [10/Jan/2024 19:32:49] code 400, message Bad request version ('À\x14À')
165.154.225.234 - - [10/Jan/2024 19:32:49] "\x16\x03\x01\x00²\x01\x00\x00®\x03\x03Ç\x96È\x12ÆÌò\x02ÞV QÑBé\x12ÃÃx\x98\x96\x15i\x04¡ù\x1f\x02\x06}v\x95\x00\x00\x1aÀ/À+À\x11À\x07À\x13À\x09À\x14À" HTTPStatus.BAD_REQUEST -
165.154.225.234 - - [10/Jan/2024 19:33:00] "GET / HTTP/1.1" 200 -
165.154.225.234 - - [10/Jan/2024 19:33:00] "GET /favicon.ico HTTP/1.1" 404 -
 * Serving Flask app 'frontend_service'
 * Debug mode: off
WARNING: This is a development server. Do not use it in a production deployment. Use a production WSGI server instead.
 * Running on all addresses (0.0.0.0)
 * Running on http://127.0.0.1:5003
 * Running on http://168.119.248.211:5003
Press CTRL+C to quit
78.154.13.190 - - [11/Jan/2024 12:53:43] "GET / HTTP/1.1" 200 -
78.154.13.190 - - [11/Jan/2024 12:53:49] "POST /register HTTP/1.1" 200 -
78.154.13.190 - - [11/Jan/2024 12:53:55] "GET / HTTP/1.1" 200 -
78.154.13.190 - - [11/Jan/2024 12:54:03] "POST /register HTTP/1.1" 200 -
78.154.13.190 - - [11/Jan/2024 12:54:08] "GET / HTTP/1.1" 200 -
78.154.13.190 - - [11/Jan/2024 12:55:53] "POST /login HTTP/1.1" 200 -
78.154.13.190 - - [11/Jan/2024 12:56:11] "GET / HTTP/1.1" 200 -
